<?xml version="1.0" encoding="utf-8"?>
<robot
  name="arm_description">
  <link
    name="world">
  </link>

  <link
    name="base_link">
    <inertial>
      <origin
        xyz="0.055 0.028511 -0.07071"
        rpy="0 0 0" />
      <mass
        value="0.22424" />
      <inertia
        ixx="1"
        ixy="1"
        ixz="0"
        iyy="1"
        iyz="0"
        izz="1" />
    </inertial>
    <visual>
      <origin
        xyz="0 0 0"
        rpy="0 0 0" />
      <geometry>
        <mesh
          filename="package://arm_description/meshes/base_link.STL" />
      </geometry>
      <material
        name="">
        <color
          rgba="0.79216 0.81961 0.93333 1" />
      </material>
    </visual>
    <collision>
      <origin
        xyz="0 0 0"
        rpy="0 0 0" />
      <geometry>
        <mesh
          filename="package://arm_description/meshes/base_link.STL" />
      </geometry>
    </collision>
  </link>
  
  <joint
    name="joint_dummy"
    type="fixed">
    <origin
      xyz="0 0 0"
      rpy="0 0 0" />
    <parent
      link="world" />
    <child
      link="base_link" />
  </joint>
  
  <link
    name="link1">
    <inertial>
      <origin
        xyz="0 -0.0739919805157646 0.00271975586057593"
        rpy="0 0 0" />
      <mass
        value="0.182986637355482" />
      <inertia
        ixx="1"
        ixy="0"
        ixz="0"
        iyy="1"
        iyz="0"
        izz="1" />
    </inertial>
    <visual>
      <origin
        xyz="0 0 0"
        rpy="0 0 0" />
      <geometry>
        <mesh
          filename="package://arm_description/meshes/link1.STL" />
      </geometry>
      <material
        name="">
        <color
          rgba="0.792156862745098 0.819607843137255 0.933333333333333 1" />
      </material>
    </visual>
    <collision>
      <origin
        xyz="0 0 0"
        rpy="0 0 0" />
      <geometry>
        <mesh
          filename="package://arm_description/meshes/link1.STL" />
      </geometry>
    </collision>
  </link>
  <joint
    name="joint1"
    type="revolute">
    <origin
      xyz="0.055 0.105 0.058"
      rpy="-1.5708 -6.123E-17 -1.5708" />
    <parent
      link="base_link" />
    <child
      link="link1" />
     <axis
      xyz="0 1 0" />
    <limit
      lower="-3.14"
      upper="3.14"
      effort="100"
      velocity="20" />
      <dynamics
        damping = "5"
        friction = "5"/>
  </joint>
  <link
    name="link2">
    <inertial>
      <origin
        xyz="9.33241508168856E-05 0.00299946771656848 0.259411152659096"
        rpy="0 0 0" />
      <mass
        value="0.15891412192705" />
      <inertia
        ixx="1"
        ixy="0"
        ixz="0"
        iyy="1"
        iyz="0"
        izz="1" />
    </inertial>
    <visual>
      <origin
        xyz="0 0 0"
        rpy="0 0 0" />
      <geometry>
        <mesh
          filename="package://arm_description/meshes/link2.STL" />
      </geometry>
      <material
        name="">
        <color
          rgba="0.792156862745098 0.819607843137255 0.933333333333333 1" />
      </material>
    </visual>
    <collision>
      <origin
        xyz="0 0 0"
        rpy="0 0 0" />
      <geometry>
        <mesh
          filename="package://arm_description/meshes/link2.STL" />
      </geometry>
    </collision>
  </link>
  <joint
    name="joint2"
    type="revolute">
    <origin
      xyz="0 -0.0975 0.0005"
      rpy="0.79351 1.5708 0" />
    <parent
      link="link1" />
    <child
      link="link2" />
     <axis
      xyz="1 0 0" />
    <limit
      lower="-3.14"
      upper="3.14"
      effort="100"
      velocity="20" />
  </joint>
  <link
    name="link3">
    <inertial>
      <origin
        xyz="-0.000140175541839031 0.00170047101330162 0.234927029132246"
        rpy="0 0 0" />
      <mass
        value="0.12508309667554" />
      <inertia
        ixx="1"
        ixy="0"
        ixz="0"
        iyy="1"
        iyz="0"
        izz="1" />
    </inertial>
    <visual>
      <origin
        xyz="0 0 0"
        rpy="0 0 0" />
      <geometry>
        <mesh
          filename="package://arm_description/meshes/link3.STL" />
      </geometry>
      <material
        name="">
        <color
          rgba="0.792156862745098 0.819607843137255 0.933333333333333 1" />
      </material>
    </visual>
    <collision>
      <origin
        xyz="0 0 0"
        rpy="0 0 0" />
      <geometry>
        <mesh
          filename="package://arm_description/meshes/link3.STL" />
      </geometry>
    </collision>
  </link>
  <joint
    name="joint3"
    type="revolute">
    <origin
      xyz="0.0245 0.0495 0.5419"
      rpy="0.83549 0 3.1416" />
    <parent
      link="link2" />
    <child
      link="link3" />
     <axis
      xyz="1 0 0" />
    <limit
      lower="-3.14"
      upper="3.14"
      effort="100"
      velocity="20" />
  </joint>
  <link
    name="link4">
    <inertial>
      <origin
        xyz="-0.00777696008671636 0.0133698565418885 0.0217435569521924"
        rpy="0 0 0" />
      <mass
        value="0.156151945009422" />
      <inertia
        ixx="1"
        ixy="0"
        ixz="0"
        iyy="1"
        iyz="0"
        izz="1" />
	</inertial>
    <visual>
      <origin
        xyz="0 0 0"
        rpy="0 0 0" />
      <geometry>
        <mesh
          filename="package://arm_description/meshes/link4.STL" />
      </geometry>
      <material
        name="">
        <color
          rgba="0.792156862745098 0.819607843137255 0.933333333333333 1" />
      </material>
    </visual>
    <collision>
      <origin
        xyz="0 0 0"
        rpy="0 0 0" />
      <geometry>
        <mesh
          filename="package://arm_description/meshes/link4.STL" />
      </geometry>
    </collision>
  </link>
  <joint
    name="joint4"
    type="revolute">
    <origin
      xyz="0.0545 0.0355 0.503"
      rpy="1.5708 -6.9389E-18 1.5708" />
    <parent
      link="link3" />
    <child
      link="link4" />
     <axis
      xyz="0 0 1" />
    <limit
      lower="-3.14"
      upper="3.14"
      effort="100"
      velocity="20" />
  </joint>
  <link
    name="link5">
    <inertial>
      <origin
        xyz="0.00423182736021133 0.00932384755029578 0.0219997086154421"
        rpy="0 0 0" />
      <mass
        value="0.153675066385186" />
      <inertia
        ixx="1"
        ixy="0"
        ixz="0"
        iyy="1"
        iyz="0"
        izz="1" />
    </inertial>
    <visual>
      <origin
        xyz="0 0 0"
        rpy="0 0 0" />
      <geometry>
        <mesh
          filename="package://arm_description/meshes/link5.STL" />
      </geometry>
      <material
        name="">
        <color
          rgba="0.792156862745098 0.819607843137255 0.933333333333333 1" />
      </material>
    </visual>
    <collision>
      <origin
        xyz="0 0 0"
        rpy="0 0 0" />
      <geometry>
        <mesh
          filename="package://arm_description/meshes/link5.STL" />
      </geometry>
    </collision>
  </link>
  <joint
    name="joint5"
    type="revolute">
    <origin
      xyz="-0.07 0.035 0.044"
      rpy="1.5708 0 -1.5708" />
    <parent
      link="link4" />
    <child
      link="link5" />
     <axis
      xyz="0 0 1" />
    <limit
      lower="-3.14"
      upper="3.14"
      effort="100"
      velocity="20" />
  </joint>
  <link
    name="link6">
    <inertial>
      <origin
        xyz="2.77555756156289E-17 1.11022302462516E-16 0.0181583763254755"
        rpy="0 0 0" />
      <mass
        value="0.299295530441066" />
      <inertia
        ixx="1"
        ixy="0"
        ixz="0"
        iyy="1"
        iyz="0"
        izz="1" />
    </inertial>
    <visual>
      <origin
        xyz="0 0 0"
        rpy="0 0 0" />
      <geometry>
        <mesh
          filename="package://arm_description/meshes/link6.STL" />
      </geometry>
      <material
        name="">
        <color
          rgba="0.898039215686275 0.917647058823529 0.929411764705882 1" />
      </material>
    </visual>
    <collision>
      <origin
        xyz="0 0 0"
        rpy="0 0 0" />
      <geometry>
        <mesh
          filename="package://arm_description/meshes/link6.STL" />
      </geometry>
    </collision>
  </link>
  <joint
    name="joint6"
    type="revolute">
    <origin
      xyz="-0.041 0.031 0.045"
      rpy="-1.5708 0 1.5708" />
    <parent
      link="link5" />
    <child
      link="link6" />
     <axis
      xyz="0 0 1" />
    <limit
      lower="-3.14"
      upper="3.14"
      effort="100"
      velocity="20" />
  </joint>
<transmission name="tran1">
    <type>transmission_interface/SimpleTransmission</type>
    <joint name="joint1">
      <hardwareInterface>hardware_interface/EffortJointInterface</hardwareInterface>
    </joint>
    <actuator name="motor1">
      <hardwareInterface>hardware_interface/EffortJointInterface</hardwareInterface>
      <mechanicalReduction>1</mechanicalReduction>
    </actuator>
  </transmission>   
<transmission name="tran2">
    <type>transmission_interface/SimpleTransmission</type>
    <joint name="joint2">
      <hardwareInterface>hardware_interface/EffortJointInterface</hardwareInterface>
    </joint>
    <actuator name="motor2">
      <hardwareInterface>hardware_interface/EffortJointInterface</hardwareInterface>
      <mechanicalReduction>1</mechanicalReduction>
    </actuator>
  </transmission> 
<transmission name="tran3">
    <type>transmission_interface/SimpleTransmission</type>
    <joint name="joint3">
      <hardwareInterface>hardware_interface/EffortJointInterface</hardwareInterface>
    </joint>
    <actuator name="motor3">
      <hardwareInterface>hardware_interface/EffortJointInterface</hardwareInterface>
      <mechanicalReduction>1</mechanicalReduction>
    </actuator>
  </transmission>
<transmission name="tran4">
    <type>transmission_interface/SimpleTransmission</type>
    <joint name="joint4">
      <hardwareInterface>hardware_interface/EffortJointInterface</hardwareInterface>
    </joint>
    <actuator name="motor4">
      <hardwareInterface>hardware_interface/EffortJointInterface</hardwareInterface>
      <mechanicalReduction>1</mechanicalReduction>
    </actuator>
  </transmission>
<transmission name="tran5">
    <type>transmission_interface/SimpleTransmission</type>
    <joint name="joint5">
      <hardwareInterface>hardware_interface/EffortJointInterface</hardwareInterface>
    </joint>
    <actuator name="motor5">
      <hardwareInterface>hardware_interface/EffortJointInterface</hardwareInterface>
      <mechanicalReduction>1</mechanicalReduction>
    </actuator>
  </transmission>
<transmission name="tran6">
    <type>transmission_interface/SimpleTransmission</type>
    <joint name="joint6">
      <hardwareInterface>hardware_interface/EffortJointInterface</hardwareInterface>
    </joint>
    <actuator name="motor6">
      <hardwareInterface>hardware_interface/EffortJointInterface</hardwareInterface>
      <mechanicalReduction>1</mechanicalReduction>
    </actuator>
  </transmission>
  <gazebo>
    <plugin name="gazebo_ros_control" filename="libgazebo_ros_control.so">
    </plugin>
  </gazebo>
</robot>
